Workbook

Sheet 00 Cover
A1: Konn3ct Volume 8 Financial Analysis Workbook
A2: Management financial model for pricing, revenue, cost, profitability, CAC/LTV, break-even and scenarios
A4: Workbook Section | B4: Purpose | C4: How Management Should Use It
A5: 01 Assumptions | B5: All scenario-driven inputs and cost assumptions | C5: Update blue/yellow input cells before management review
A6: 02 User Forecast | B6: Free users, paid users, conversion, churn and operational volume | C6: Review user growth and paid conversion assumptions
A7: 03 Revenue Forecast | B7: Subscription, webinar, replay, donation, enterprise, API and partner revenue | C7: Track revenue stream contribution and growth
A8: 04 Cost Forecast | B8: Direct service costs and operating costs | C8: Understand cost pressure and margin risk
A9: 05 Profitability | B9: Gross profit, EBITDA, cash flow and cumulative performance | C9: Assess sustainability and runway
A10: 06 Gross Margin | B10: Margin by revenue stream | C10: Prioritize high-margin commercial focus areas
A11: 07 CAC LTV | B11: Customer acquisition, lifetime value and retention economics | C11: Control sales efficiency and churn
A12: 08 Break Even | B12: Month-by-month break-even analysis | C12: Identify when the business becomes self-sustaining
A13: 09 Scenarios | B13: Conservative, Base and Aggressive model comparison | C13: Compare growth and profitability paths
A14: 10–13 Revenue Detail Tabs | B14: Meeting, webinar, replay, enterprise, API and partner detail | C14: Use for package and pricing design
A15: 14 Dashboard | B15: Executive KPI view | C15: Use for board/management discussions
A16: 15 Sources | B16: Model sources, notes and usage guidance | C16: Keep assumptions transparent
A18: Key Workbook Rule
A19: Blue/yellow cells are hardcoded management inputs. Green cells are workbook links. Black cells are formulas. Replace assumptions with actual Konn3ct operating data as the platform matures.

Sheet 01 Assumptions
A1: 01 Assumptions
A2: Scenario-driven assumptions for users, revenue, pricing, costs and profitability
A4: Assumption | B4: Conservative | C4: Base | D4: Aggressive | E4: Selected Value | F4: Unit | G4: Source / Management Note
A5: Selected Scenario | C5: Base | E5: =$C$5 -> Base | F5: Text | G5: Choose Conservative, Base or Aggressive in C5
A6: Starting Free Users | B6: 5000 | C6: 10000 | D6: 20000 | E6: =INDEX(B6:D6,1,MATCH($C$5,$B$4:$D$4,0)) -> 10000 | F6: Users | G6: Management planning assumption
A7: Starting Paid Users | B7: 150 | C7: 350 | D7: 750 | E7: =INDEX(B7:D7,1,MATCH($C$5,$B$4:$D$4,0)) -> 350 | F7: Users | G7: Management planning assumption
A8: Free User Monthly Growth Rate | B8: 0.06 | C8: 0.1 | D8: 0.16 | E8: =INDEX(B8:D8,1,MATCH($C$5,$B$4:$D$4,0)) -> 0.1 | F8: % | G8: Marketing and organic growth assumption
A9: Free-to-Paid Monthly Conversion Rate | B9: 0.018 | C9: 0.035 | D9: 0.06 | E9: =INDEX(B9:D9,1,MATCH($C$5,$B$4:$D$4,0)) -> 0.035 | F9: % | G9: Conversion assumption from free usage to paid value
A10: Paid User Monthly Churn Rate | B10: 0.055 | C10: 0.035 | D10: 0.022 | E10: =INDEX(B10:D10,1,MATCH($C$5,$B$4:$D$4,0)) -> 0.035 | F10: % | G10: Retention / churn assumption
A11: Subscription ARPU per Paid User | B11: 1800 | C11: 2800 | D11: 4200 | E11: =INDEX(B11:D11,1,MATCH($C$5,$B$4:$D$4,0)) -> 2800 | F11: NGN / Month | G11: Average monthly subscription revenue per paid user
A12: Meeting Add-On Revenue per Paid User | B12: 100 | C12: 250 | D12: 550 | E12: =INDEX(B12:D12,1,MATCH($C$5,$B$4:$D$4,0)) -> 250 | F12: NGN / Month | G12: Capacity, storage, AI and support add-ons
A13: Webinar Events in Month 1 | B13: 8 | C13: 20 | D13: 45 | E13: =INDEX(B13:D13,1,MATCH($C$5,$B$4:$D$4,0)) -> 20 | F13: Events | G13: Paid or monetizable events per month
A14: Webinar Event Monthly Growth Rate | B14: 0.04 | C14: 0.09 | D14: 0.15 | E14: =INDEX(B14:D14,1,MATCH($C$5,$B$4:$D$4,0)) -> 0.09 | F14: % | G14: Growth in monetized events
A15: Average Paid Tickets per Webinar/Event | B15: 60 | C15: 150 | D15: 300 | E15: =INDEX(B15:D15,1,MATCH($C$5,$B$4:$D$4,0)) -> 150 | F15: Tickets | G15: Average paid attendees per event
A16: Average Ticket Price | B16: 2000 | C16: 3500 | D16: 5000 | E16: =INDEX(B16:D16,1,MATCH($C$5,$B$4:$D$4,0)) -> 3500 | F16: NGN | G16: Average customer ticket price
A17: Konn3ct Ticketing Platform Fee | B17: 0.1 | C17: 0.12 | D17: 0.15 | E17: =INDEX(B17:D17,1,MATCH($C$5,$B$4:$D$4,0)) -> 0.12 | F17: % | G17: Platform transaction fee on event GMV
... A49: Starting Cash | B49: 5000000 | C49: 10000000 | D49: 25000000 | E49: =INDEX(B49:D49,1,MATCH($C$5,$B$4:$D$4,0)) -> 10000000 | F49: NGN | G49: Opening cash available for product growth
E50: =INDEX(B50:D50,1,MATCH($C$5,$B$4:$D$4,0)) -> 0

Sheet 02 User Forecast
A1: 02 User Forecast
A2: Free users, paid users, conversion, churn and commercial volume drivers
A5: Metric | B5: Month 1 | C5: Month 2 | D5: Month 3 | E5: Month 4 | F5: Month 5 | G5: Month 6 | H5: Month 7 | I5: Month 8 | J5: Month 9 | K5: Month 10 | L5: Month 11 | M5: Month 12 | N5: Month 13 | O5: Month 14 | P5: Month 15 | Q5: Month 16 | R5: Month 17 | S5: Month 18 | T5: Month 19 | U5: Month 20 | V5: Month 21 | W5: Month 22 | X5: Month 23 | Y5: Month 24 | Z5: Month 25 | AA5: Month 26 | AB5: Month 27 | AC5: Month 28 | AD5: Month 29 | AE5: Month 30 | AF5: Month 31 | AG5: Month 32 | AH5: Month 33 | AI5: Month 34 | AJ5: Month 35 | AK5: Month 36
A6: Opening Free Users | B6: ='01 Assumptions'!$E$6 -> 10000 | C6: =B9 -> 10650 | D6: =C9 -> 11342.25 | E6: =D9 -> 12079.496 | F6: =E9 -> 12864.664 | G6: =F9 -> 13700.867 | H6: =G9 -> 14591.423 | I6: =H9 -> 15539.865 | J6: =I9 -> 16549.957 | ... AK6: =AJ9 -> 90622.549
A7: Gross New Free Users | B7: =B6*'01 Assumptions'!$E$8 -> 1000 | C7: =C6*'01 Assumptions'!$E$8 -> 1065 | D7: =D6*'01 Assumptions'!$E$8 -> 1134.225 | E7: =E6*'01 Assumptions'!$E$8 -> 1207.9496 | F7: =F6*'01 Assumptions'!$E$8 -> 1286.4664 | G7: =G6*'01 Assumptions'!$E$8 -> 1370.0867 | H7: =H6*'01 Assumptions'!$E$8 -> 1459.1423 | I7: =I6*'01 Assumptions'!$E$8 -> 1553.9865 | ... AK7: =AK6*'01 Assumptions'!$E$8 -> 9062.2549
A8: New Paid Conversions | B8: =B6*'01 Assumptions'!$E$9 -> 350 | C8: =C6*'01 Assumptions'!$E$9 -> 372.75 | D8: =D6*'01 Assumptions'!$E$9 -> 396.97875 | E8: =E6*'01 Assumptions'!$E$9 -> 422.78237 | F8: =F6*'01 Assumptions'!$E$9 -> 450.26322 | G8: =G6*'01 Assumptions'!$E$9 -> 479.53033 | H8: =H6*'01 Assumptions'!$E$9 -> 510.6998 | I8: =I6*'01 Assumptions'!$E$9 -> 543.89529 | ... AK8: =AK6*'01 Assumptions'!$E$9 -> 3171.7892
A9: Closing Free Users | B9: =MAX(0,B6+B7-B8) -> 10650 | C9: =MAX(0,C6+C7-C8) -> 11342.25 | D9: =MAX(0,D6+D7-D8) -> 12079.496 | E9: =MAX(0,E6+E7-E8) -> 12864.664 | F9: =MAX(0,F6+F7-F8) -> 13700.867 | G9: =MAX(0,G6+G7-G8) -> 14591.423 | H9: =MAX(0,H6+H7-H8) -> 15539.865 | I9: =MAX(0,I6+I7-I8) -> 16549.957 | ... AK9: =MAX(0,AK6+AK7-AK8) -> 96513.014
A10: Opening Paid Users | B10: ='01 Assumptions'!$E$7 -> 350 | C10: =B12 -> 687.75 | D10: =C12 -> 1036.4288 | E10: =D12 -> 1397.1325 | F10: =E12 -> 1771.0152 | G10: =F12 -> 2159.2929 | H10: =G12 -> 2563.248 | I10: =H12 -> 2984.2341 | J10: =I12 -> 3423.6812 | ... AK10: =AJ12 -> 30812.646
A11: Paid User Churn | B11: =B10*'01 Assumptions'!$E$10 -> 12.25 | C11: =C10*'01 Assumptions'!$E$10 -> 24.07125 | D11: =D10*'01 Assumptions'!$E$10 -> 36.275006 | E11: =E10*'01 Assumptions'!$E$10 -> 48.899637 | F11: =F10*'01 Assumptions'!$E$10 -> 61.985533 | G11: =G10*'01 Assumptions'!$E$10 -> 75.575252 | H11: =H10*'01 Assumptions'!$E$10 -> 89.71368 | I11: =I10*'01 Assumptions'!$E$10 -> 104.44819 | ... AK11: =AK10*'01 Assumptions'!$E$10 -> 1078.4426
A12: Closing Paid Users | B12: =MAX(0,B10+B8-B11) -> 687.75 | C12: =MAX(0,C10+C8-C11) -> 1036.4288 | D12: =MAX(0,D10+D8-D11) -> 1397.1325 | E12: =MAX(0,E10+E8-E11) -> 1771.0152 | F12: =MAX(0,F10+F8-F11) -> 2159.2929 | G12: =MAX(0,G10+G8-G11) -> 2563.248 | H12: =MAX(0,H10+H8-H11) -> 2984.2341 | I12: =MAX(0,I10+I8-I11) -> 3423.6812 | ... AK12: =MAX(0,AK10+AK8-AK11) -> 32905.993
A13: Total Active Users | B13: =B9+B12 -> 11337.75 | C13: =C9+C12 -> 12378.679 | D13: =D9+D12 -> 13476.629 | E13: =E9+E12 -> 14635.679 | F13: =F9+F12 -> 15860.16 | G13: =G9+G12 -> 17154.671 | H13: =H9+H12 -> 18524.1 | I13: =I9+I12 -> 19973.638 | ... AK13: =AK9+AK12 -> 129419.01
A14: New Paid Users | B14: =B8 -> 350 | C14: =C8 -> 372.75 | D14: =D8 -> 396.97875 | E14: =E8 -> 422.78237 | F14: =F8 -> 450.26322 | G14: =G8 -> 479.53033 | H14: =H8 -> 510.6998 | I14: =I8 -> 543.89529 | ... AK14: =AK8 -> 3171.7892
A15: Free-to-Paid Conversion Rate | B15: =IFERROR(B8/B6,0) -> 0.035 | C15: =IFERROR(C8/C6,0) -> 0.035 | D15: =IFERROR(D8/D6,0) -> 0.035 | E15: =IFERROR(E8/E6,0) -> 0.035 | F15: =IFERROR(F8/F6,0) -> 0.035 | G15: =IFERROR(G8/G6,0) -> 0.035 | H15: =IFERROR(H8/H6,0) -> 0.035 | I15: =IFERROR(I8/I6,0) -> 0.035 | ... AK15: =IFERROR(AK8/AK6,0) -> 0.035
A16: Paid User Churn Rate | B16: ='01 Assumptions'!$E$10 -> 0.035 | C16: ='01 Assumptions'!$E$10 -> 0.035 | D16: ='01 Assumptions'!$E$10 -> 0.035 | E16: ='01 Assumptions'!$E$10 -> 0.035 | F16: ='01 Assumptions'!$E$10 -> 0.035 | G16: ='01 Assumptions'!$E$10 -> 0.035 | H16: ='01 Assumptions'!$E$10 -> 0.035 | I16: ='01 Assumptions'!$E$10 -> 0.035 | ... AK16: ='01 Assumptions'!$E$10 -> 0.035
A17: Webinar/Event Count | B17: ='01 Assumptions'!$E$13 -> 20 | C17: =B17*(1+'01 Assumptions'!$E$14) -> 21.8 | D17: =C17*(1+'01 Assumptions'!$E$14) -> 23.762 | E17: =D17*(1+'01 Assumptions'!$E$14) -> 25.90058 | F17: =E17*(1+'01 Assumptions'!$E$14) -> 28.231632 | G17: =F17*(1+'01 Assumptions'!$E$14) -> 30.772479 | H17: =G17*(1+'01 Assumptions'!$E$14) -> 33.542002 | I17: =H17*(1+'01 Assumptions'!$E$14) -> 36.560782 | J17: =I17*(1+'01 Assumptions'!$E$14) -> 39.851253 | ... AK17: =AJ17*(1+'01 Assumptions'!$E$14) -> 408.27936
A18: Paid Tickets Sold | B18: =B17*'01 Assumptions'!$E$15 -> 3000 | C18: =C17*'01 Assumptions'!$E$15 -> 3270 | D18: =D17*'01 Assumptions'!$E$15 -> 3564.3 | E18: =E17*'01 Assumptions'!$E$15 -> 3885.087 | F18: =F17*'01 Assumptions'!$E$15 -> 4234.7448 | G18: =G17*'01 Assumptions'!$E$15 -> 4615.8719 | H18: =H17*'01 Assumptions'!$E$15 -> 5031.3003 | I18: =I17*'01 Assumptions'!$E$15 -> 5484.1174 | ... AK18: =AK17*'01 Assumptions'!$E$15 -> 61241.904
A19: Paid Replay Purchases | B19: ='01 Assumptions'!$E$18 -> 250 | C19: =B19*(1+'01 Assumptions'!$E$19) -> 275 | D19: =C19*(1+'01 Assumptions'!$E$19) -> 302.5 | E19: =D19*(1+'01 Assumptions'!$E$19) -> 332.75 | F19: =E19*(1+'01 Assumptions'!$E$19) -> 366.025 | G19: =F19*(1+'01 Assumptions'!$E$19) -> 402.6275 | H19: =G19*(1+'01 Assumptions'!$E$19) -> 442.89025 | I19: =H19*(1+'01 Assumptions'!$E$19) -> 487.17928 | J19: =I19*(1+'01 Assumptions'!$E$19) -> 535.8972 | ... AK19: =AJ19*(1+'01 Assumptions'!$E$19) -> 7025.6092
A20: Enterprise Accounts | B20: ='01 Assumptions'!$E$25 -> 3 | C20: =B20+'01 Assumptions'!$E$26 -> 3.75 | D20: =C20+'01 Assumptions'!$E$26 -> 4.5 | E20: =D20+'01 Assumptions'!$E$26 -> 5.25 | F20: =E20+'01 Assumptions'!$E$26 -> 6 | G20: =F20+'01 Assumptions'!$E$26 -> 6.75 | H20: =G20+'01 Assumptions'!$E$26 -> 7.5 | I20: =H20+'01 Assumptions'!$E$26 -> 8.25 | J20: =I20+'01 Assumptions'!$E$26 -> 9 | ... AK20: =AJ20+'01 Assumptions'!$E$26 -> 29.25
A21: API/Embedded Accounts | B21: ='01 Assumptions'!$E$28 -> 1 | C21: =B21+'01 Assumptions'!$E$29 -> 1.35 | D21: =C21+'01 Assumptions'!$E$29 -> 1.7 | E21: =D21+'01 Assumptions'!$E$29 -> 2.05 | F21: =E21+'01 Assumptions'!$E$29 -> 2.4 | G21: =F21+'01 Assumptions'!$E$29 -> 2.75 | H21: =G21+'01 Assumptions'!$E$29 -> 3.1 | I21: =H21+'01 Assumptions'!$E$29 -> 3.45 | J21: =I21+'01 Assumptions'!$E$29 -> 3.8 | ... AK21: =AJ21+'01 Assumptions'!$E$29 -> 13.25

Sheet 03 Revenue Forecast
A1: 03 Revenue Forecast
A2: Revenue by stream: meeting subscriptions, webinars, paid replay, donations, enterprise, API and partner revenue
A5: Metric | B5: Month 1 | C5: Month 2 | D5: Month 3 | E5: Month 4 | F5: Month 5 | G5: Month 6 | H5: Month 7 | I5: Month 8 | J5: Month 9 | K5: Month 10 | L5: Month 11 | M5: Month 12 | N5: Month 13 | O5: Month 14 | P5: Month 15 | Q5: Month 16 | R5: Month 17 | S5: Month 18 | T5: Month 19 | U5: Month 20 | V5: Month 21 | W5: Month 22 | X5: Month 23 | Y5: Month 24 | Z5: Month 25 | AA5: Month 26 | AB5: Month 27 | AC5: Month 28 | AD5: Month 29 | AE5: Month 30 | AF5: Month 31 | AG5: Month 32 | AH5: Month 33 | AI5: Month 34 | AJ5: Month 35 | AK5: Month 36
A6: Meeting Subscription Revenue | B6: ='02 User Forecast'!B12*'01 Assumptions'!$E$11 -> 1925700 | C6: ='02 User Forecast'!C12*'01 Assumptions'!$E$11 -> 2902000.5 | D6: ='02 User Forecast'!D12*'01 Assumptions'!$E$11 -> 3911971 | E6: ='02 User Forecast'!E12*'01 Assumptions'!$E$11 -> 4958842.6 | F6: ='02 User Forecast'!F12*'01 Assumptions'!$E$11 -> 6046020.2 | G6: ='02 User Forecast'!G12*'01 Assumptions'!$E$11 -> 7177094.4 | H6: ='02 User Forecast'!H12*'01 Assumptions'!$E$11 -> 8355855.5 | I6: ='02 User Forecast'!I12*'01 Assumptions'!$E$11 -> 9586307.4 | ... AK6: ='02 User Forecast'!AK12*'01 Assumptions'!$E$11 -> 92136780
A7: Meeting Add-On Revenue | B7: ='02 User Forecast'!B12*'01 Assumptions'!$E$12 -> 171937.5 | C7: ='02 User Forecast'!C12*'01 Assumptions'!$E$12 -> 259107.19 | D7: ='02 User Forecast'!D12*'01 Assumptions'!$E$12 -> 349283.12 | E7: ='02 User Forecast'!E12*'01 Assumptions'!$E$12 -> 442753.81 | F7: ='02 User Forecast'!F12*'01 Assumptions'!$E$12 -> 539823.23 | G7: ='02 User Forecast'!G12*'01 Assumptions'!$E$12 -> 640812 | H7: ='02 User Forecast'!H12*'01 Assumptions'!$E$12 -> 746058.53 | I7: ='02 User Forecast'!I12*'01 Assumptions'!$E$12 -> 855920.3 | ... AK7: ='02 User Forecast'!AK12*'01 Assumptions'!$E$12 -> 8226498.2
A8: Webinar Ticket GMV | B8: ='02 User Forecast'!B18*'01 Assumptions'!$E$16 -> 10500000 | C8: ='02 User Forecast'!C18*'01 Assumptions'!$E$16 -> 11445000 | D8: ='02 User Forecast'!D18*'01 Assumptions'!$E$16 -> 12475050 | E8: ='02 User Forecast'!E18*'01 Assumptions'!$E$16 -> 13597804 | F8: ='02 User Forecast'!F18*'01 Assumptions'!$E$16 -> 14821607 | G8: ='02 User Forecast'!G18*'01 Assumptions'!$E$16 -> 16155552 | H8: ='02 User Forecast'!H18*'01 Assumptions'!$E$16 -> 17609551 | I8: ='02 User Forecast'!I18*'01 Assumptions'!$E$16 -> 19194411 | ... AK8: ='02 User Forecast'!AK18*'01 Assumptions'!$E$16 -> 2.1434666e+08
A9: Webinar/Event Platform Fee Revenue | B9: =B8*'01 Assumptions'!$E$17 -> 1260000 | C9: =C8*'01 Assumptions'!$E$17 -> 1373400 | D9: =D8*'01 Assumptions'!$E$17 -> 1497006 | E9: =E8*'01 Assumptions'!$E$17 -> 1631736.5 | F9: =F8*'01 Assumptions'!$E$17 -> 1778592.8 | G9: =G8*'01 Assumptions'!$E$17 -> 1938666.2 | H9: =H8*'01 Assumptions'!$E$17 -> 2113146.1 | I9: =I8*'01 Assumptions'!$E$17 -> 2303329.3 | ... AK9: =AK8*'01 Assumptions'!$E$17 -> 25721600
A10: Paid Replay GMV | B10: ='02 User Forecast'!B19*'01 Assumptions'!$E$20 -> 500000 | C10: ='02 User Forecast'!C19*'01 Assumptions'!$E$20 -> 550000 | D10: ='02 User Forecast'!D19*'01 Assumptions'!$E$20 -> 605000 | E10: ='02 User Forecast'!E19*'01 Assumptions'!$E$20 -> 665500 | F10: ='02 User Forecast'!F19*'01 Assumptions'!$E$20 -> 732050 | G10: ='02 User Forecast'!G19*'01 Assumptions'!$E$20 -> 805255 | H10: ='02 User Forecast'!H19*'01 Assumptions'!$E$20 -> 885780.5 | I10: ='02 User Forecast'!I19*'01 Assumptions'!$E$20 -> 974358.55 | ... AK10: ='02 User Forecast'!AK19*'01 Assumptions'!$E$20 -> 14051218
A11: Paid Replay Platform Revenue | B11: =B10*'01 Assumptions'!$E$21 -> 200000 | C11: =C10*'01 Assumptions'!$E$21 -> 220000 | D11: =D10*'01 Assumptions'!$E$21 -> 242000 | E11: =E10*'01 Assumptions'!$E$21 -> 266200 | F11: =F10*'01 Assumptions'!$E$21 -> 292820 | G11: =G10*'01 Assumptions'!$E$21 -> 322102 | H11: =H10*'01 Assumptions'!$E$21 -> 354312.2 | I11: =I10*'01 Assumptions'!$E$21 -> 389743.42 | ... AK11: =AK10*'01 Assumptions'!$E$21 -> 5620487.4
A12: Donation GMV | B12: ='01 Assumptions'!$E$22 -> 750000 | C12: =B12*(1+'01 Assumptions'!$E$23) -> 810000 | D12: =C12*(1+'01 Assumptions'!$E$23) -> 874800 | E12: =D12*(1+'01 Assumptions'!$E$23) -> 944784 | F12: =E12*(1+'01 Assumptions'!$E$23) -> 1020366.7 | G12: =F12*(1+'01 Assumptions'!$E$23) -> 1101996.1 | H12: =G12*(1+'01 Assumptions'!$E$23) -> 1190155.7 | I12: =H12*(1+'01 Assumptions'!$E$23) -> 1285368.2 | J12: =I12*(1+'01 Assumptions'!$E$23) -> 1388197.7 | ... AK12: =AJ12*(1+'01 Assumptions'!$E$23) -> 11089008
A13: Donation Platform Revenue | B13: =B12*'01 Assumptions'!$E$24 -> 30000 | C13: =C12*'01 Assumptions'!$E$24 -> 32400 | D13: =D12*'01 Assumptions'!$E$24 -> 34992 | E13: =E12*'01 Assumptions'!$E$24 -> 37791.36 | F13: =F12*'01 Assumptions'!$E$24 -> 40814.669 | G13: =G12*'01 Assumptions'!$E$24 -> 44079.842 | H13: =H12*'01 Assumptions'!$E$24 -> 47606.23 | I13: =I12*'01 Assumptions'!$E$24 -> 51414.728 | ... AK13: =AK12*'01 Assumptions'!$E$24 -> 443560.33
A14: Enterprise Revenue | B14: ='02 User Forecast'!B20*'01 Assumptions'!$E$27 -> 900000 | C14: ='02 User Forecast'!C20*'01 Assumptions'!$E$27 -> 1125000 | D14: ='02 User Forecast'!D20*'01 Assumptions'!$E$27 -> 1350000 | E14: ='02 User Forecast'!E20*'01 Assumptions'!$E$27 -> 1575000 | F14: ='02 User Forecast'!F20*'01 Assumptions'!$E$27 -> 1800000 | G14: ='02 User Forecast'!G20*'01 Assumptions'!$E$27 -> 2025000 | H14: ='02 User Forecast'!H20*'01 Assumptions'!$E$27 -> 2250000 | I14: ='02 User Forecast'!I20*'01 Assumptions'!$E$27 -> 2475000 | ... AK14: ='02 User Forecast'!AK20*'01 Assumptions'!$E$27 -> 8775000
A15: API/Embedded Revenue | B15: ='02 User Forecast'!B21*'01 Assumptions'!$E$30 -> 180000 | C15: ='02 User Forecast'!C21*'01 Assumptions'!$E$30 -> 243000 | D15: ='02 User Forecast'!D21*'01 Assumptions'!$E$30 -> 306000 | E15: ='02 User Forecast'!E21*'01 Assumptions'!$E$30 -> 369000 | F15: ='02 User Forecast'!F21*'01 Assumptions'!$E$30 -> 432000 | G15: ='02 User Forecast'!G21*'01 Assumptions'!$E$30 -> 495000 | H15: ='02 User Forecast'!H21*'01 Assumptions'!$E$30 -> 558000 | I15: ='02 User Forecast'!I21*'01 Assumptions'!$E$30 -> 621000 | ... AK15: ='02 User Forecast'!AK21*'01 Assumptions'!$E$30 -> 2385000
A16: Partner-Driven Revenue | B16: =SUM(B6,B7,B9,B11,B13,B14,B15)*'01 Assumptions'!$E$31 -> 466763.75 | C16: =SUM(C6,C7,C9,C11,C13,C14,C15)*'01 Assumptions'!$E$31 -> 615490.77 | D16: =SUM(D6,D7,D9,D11,D13,D14,D15)*'01 Assumptions'!$E$31 -> 769125.21 | E16: =SUM(E6,E7,E9,E11,E13,E14,E15)*'01 Assumptions'!$E$31 -> 928132.43 | F16: =SUM(F6,F7,F9,F11,F13,F14,F15)*'01 Assumptions'!$E$31 -> 1093007.1 | G16: =SUM(G6,G7,G9,G11,G13,G14,G15)*'01 Assumptions'!$E$31 -> 1264275.4 | H16: =SUM(H6,H7,H9,H11,H13,H14,H15)*'01 Assumptions'!$E$31 -> 1442497.9 | I16: =SUM(I6,I7,I9,I11,I13,I14,I15)*'01 Assumptions'!$E$31 -> 1628271.5 | ... AK16: =SUM(AK6,AK7,AK9,AK11,AK13,AK14,AK15)*'01 Assumptions'!$E$31 -> 14330893
A17: Total Konn3ct Revenue | B17: =SUM(B6,B7,B9,B11,B13,B14,B15,B16) -> 5134401.2 | C17: =SUM(C6,C7,C9,C11,C13,C14,C15,C16) -> 6770398.5 | D17: =SUM(D6,D7,D9,D11,D13,D14,D15,D16) -> 8460377.3 | E17: =SUM(E6,E7,E9,E11,E13,E14,E15,E16) -> 10209457 | F17: =SUM(F6,F7,F9,F11,F13,F14,F15,F16) -> 12023078 | G17: =SUM(G6,G7,G9,G11,G13,G14,G15,G16) -> 13907030 | H17: =SUM(H6,H7,H9,H11,H13,H14,H15,H16) -> 15867476 | I17: =SUM(I6,I7,I9,I11,I13,I14,I15,I16) -> 17910987 | ... AK17: =SUM(AK6,AK7,AK9,AK11,AK13,AK14,AK15,AK16) -> 1.5763982e+08
A18: Total Platform GMV | B18: =SUM(B6,B7,B8,B10,B12,B14,B15) -> 14927638 | C18: =SUM(C6,C7,C8,C10,C12,C14,C15) -> 17334108 | D18: =SUM(D6,D7,D8,D10,D12,D14,D15) -> 19872104 | E18: =SUM(E6,E7,E8,E10,E12,E14,E15) -> 22553685 | F18: =SUM(F6,F7,F8,F10,F12,F14,F15) -> 25391867 | G18: =SUM(G6,G7,G8,G10,G12,G14,G15) -> 28400709 | H18: =SUM(H6,H7,H8,H10,H12,H14,H15) -> 31595401 | I18: =SUM(I6,I7,I8,I10,I12,I14,I15) -> 34992365 | ... AK18: =SUM(AK6,AK7,AK8,AK10,AK12,AK14,AK15) -> 3.5101017e+08
A19: Revenue Growth % | B19: =0 -> 0 | C19: =IFERROR(C17/B17-1,0) -> 0.31863447 | D19: =IFERROR(D17/C17-1,0) -> 0.24961291 | E19: =IFERROR(E17/D17-1,0) -> 0.20673776 | F19: =IFERROR(F17/E17-1,0) -> 0.1776413 | G19: =IFERROR(G17/F17-1,0) -> 0.15669464 | H19: =IFERROR(H17/G17-1,0) -> 0.14096803 | I19: =IFERROR(I17/H17-1,0) -> 0.12878608 | J19: =IFERROR(J17/I17-1,0) -> 0.11912123 | ... AK19: =IFERROR(AK17/AJ17-1,0) -> 0.069720204

Sheet 04 Cost Forecast
A1: 04 Cost Forecast
A2: Direct service costs, operating costs and total cost forecast
A5: Metric | B5: Month 1 | C5: Month 2 | D5: Month 3 | E5: Month 4 | F5: Month 5 | G5: Month 6 | H5: Month 7 | I5: Month 8 | J5: Month 9 | K5: Month 10 | L5: Month 11 | M5: Month 12 | N5: Month 13 | O5: Month 14 | P5: Month 15 | Q5: Month 16 | R5: Month 17 | S5: Month 18 | T5: Month 19 | U5: Month 20 | V5: Month 21 | W5: Month 22 | X5: Month 23 | Y5: Month 24 | Z5: Month 25 | AA5: Month 26 | AB5: Month 27 | AC5: Month 28 | AD5: Month 29 | AE5: Month 30 | AF5: Month 31 | AG5: Month 32 | AH5: Month 33 | AI5: Month 34 | AJ5: Month 35 | AK5: Month 36
A6: Cloud Compute Cost | B6: ='01 Assumptions'!$E$34*(1+0.01)^0 -> 1800000 | C6: ='01 Assumptions'!$E$34*(1+0.01)^1 -> 1818000 | D6: ='01 Assumptions'!$E$34*(1+0.01)^2 -> 1836180 | E6: ='01 Assumptions'!$E$34*(1+0.01)^3 -> 1854541.8 | F6: ='01 Assumptions'!$E$34*(1+0.01)^4 -> 1873087.2 | G6: ='01 Assumptions'!$E$34*(1+0.01)^5 -> 1891818.1 | H6: ='01 Assumptions'!$E$34*(1+0.01)^6 -> 1910736.3 | I6: ='01 Assumptions'!$E$34*(1+0.01)^7 -> 1929843.6 | J6: ='01 Assumptions'!$E$34*(1+0.01)^8 -> 1949142.1 | K6: ='01 Assumptions'!$E$34*(1+0.01)^9 -> 1968633.5 | L6: ='01 Assumptions'!$E$34*(1+0.01)^10 -> 1988319.8 | M6: ='01 Assumptions'!$E$34*(1+0.01)^11 -> 2008203 | N6: ='01 Assumptions'!$E$34*(1+0.01)^12 -> 2028285.1 | O6: ='01 Assumptions'!$E$34*(1+0.01)^13 -> 2048567.9 | P6: ='01 Assumptions'!$E$34*(1+0.01)^14 -> 2069053.6 | Q6: ='01 Assumptions'!$E$34*(1+0.01)^15 -> 2089744.1 | R6: ='01 Assumptions'!$E$34*(1+0.01)^16 -> 2110641.6 | S6: ='01 Assumptions'!$E$34*(1+0.01)^17 -> 2131748 | T6: ='01 Assumptions'!$E$34*(1+0.01)^18 -> 2153065.5 | U6: ='01 Assumptions'!$E$34*(1+0.01)^19 -> 2174596.1 | V6: ='01 Assumptions'!$E$34*(1+0.01)^20 -> 2196342.1 | W6: ='01 Assumptions'!$E$34*(1+0.01)^21 -> 2218305.5 | X6: ='01 Assumptions'!$E$34*(1+0.01)^22 -> 2240488.5 | Y6: ='01 Assumptions'!$E$34*(1+0.01)^23 -> 2262893.4 | Z6: ='01 Assumptions'!$E$34*(1+0.01)^24 -> 2285522.4 | AA6: ='01 Assumptions'!$E$34*(1+0.01)^25 -> 2308377.6 | AB6: ='01 Assumptions'!$E$34*(1+0.01)^26 -> 2331461.4 | AC6: ='01 Assumptions'!$E$34*(1+0.01)^27 -> 2354776 | AD6: ='01 Assumptions'!$E$34*(1+0.01)^28 -> 2378323.7 | AE6: ='01 Assumptions'!$E$34*(1+0.01)^29 -> 2402107 | AF6: ='01 Assumptions'!$E$34*(1+0.01)^30 -> 2426128 | AG6: ='01 Assumptions'!$E$34*(1+0.01)^31 -> 2450389.3 | AH6: ='01 Assumptions'!$E$34*(1+0.01)^32 -> 2474893.2 | AI6: ='01 Assumptions'!$E$34*(1+0.01)^33 -> 2499642.2 | AJ6: ='01 Assumptions'!$E$34*(1+0.01)^34 -> 2524638.6 | AK6: ='01 Assumptions'!$E$34*(1+0.01)^35 -> 2549885
A7: Media/SFU Cost | B7: ='01 Assumptions'!$E$35+'02 User Forecast'!B12*50+'02 User Forecast'!B18*20 -> 1594387.5 | C7: ='01 Assumptions'!$E$35+'02 User Forecast'!C12*50+'02 User Forecast'!C18*20 -> 1617221.4 | D7: ='01 Assumptions'!$E$35+'02 User Forecast'!D12*50+'02 User Forecast'!D18*20 -> 1641142.6 | E7: ='01 Assumptions'!$E$35+'02 User Forecast'!E12*50+'02 User Forecast'!E18*20 -> 1666252.5 | F7: ='01 Assumptions'!$E$35+'02 User Forecast'!F12*50+'02 User Forecast'!F18*20 -> 1692659.5 | G7: ='01 Assumptions'!$E$35+'02 User Forecast'!G12*50+'02 User Forecast'!G18*20 -> 1720479.8 | H7: ='01 Assumptions'!$E$35+'02 User Forecast'!H12*50+'02 User Forecast'!H18*20 -> 1749837.7 | I7: ='01 Assumptions'!$E$35+'02 User Forecast'!I12*50+'02 User Forecast'!I18*20 -> 1780866.4 | ... AK7: ='01 Assumptions'!$E$35+'02 User Forecast'!AK12*50+'02 User Forecast'!AK18*20 -> 4370137.7
A8: Bandwidth/TURN Cost | B8: ='02 User Forecast'!B13*20+'02 User Forecast'!B18*35+'02 User Forecast'!B19*15 -> 335505 | C8: ='02 User Forecast'!C13*20+'02 User Forecast'!C18*35+'02 User Forecast'!C19*15 -> 366148.58 | D8: ='02 User Forecast'!D13*20+'02 User Forecast'!D18*35+'02 User Forecast'!D19*15 -> 398820.57 | E8: ='02 User Forecast'!E13*20+'02 User Forecast'!E18*35+'02 User Forecast'!E19*15 -> 433682.87 | F8: ='02 User Forecast'!F13*20+'02 User Forecast'!F18*35+'02 User Forecast'!F19*15 -> 470909.64 | G8: ='02 User Forecast'!G13*20+'02 User Forecast'!G18*35+'02 User Forecast'!G19*15 -> 510688.35 | H8: ='02 User Forecast'!H13*20+'02 User Forecast'!H18*35+'02 User Forecast'!H19*15 -> 553220.86 | I8: ='02 User Forecast'!I13*20+'02 User Forecast'!I18*35+'02 User Forecast'!I19*15 -> 598724.56 | ... AK8: ='02 User Forecast'!AK13*20+'02 User Forecast'!AK18*35+'02 User Forecast'!AK19*15 -> 4837230.9
A9: Storage/CDN Cost | B9: ='02 User Forecast'!B19*'01 Assumptions'!$E$48+'02 User Forecast'!B12*10 -> 16877.5 | C9: ='02 User Forecast'!C19*'01 Assumptions'!$E$48+'02 User Forecast'!C12*10 -> 21364.287 | D9: ='02 User Forecast'!D19*'01 Assumptions'!$E$48+'02 User Forecast'!D12*10 -> 26071.325 | E9: ='02 User Forecast'!E19*'01 Assumptions'!$E$48+'02 User Forecast'!E12*10 -> 31020.152 | F9: ='02 User Forecast'!F19*'01 Assumptions'!$E$48+'02 User Forecast'!F12*10 -> 36233.929 | G9: ='02 User Forecast'!G19*'01 Assumptions'!$E$48+'02 User Forecast'!G12*10 -> 41737.58 | H9: ='02 User Forecast'!H19*'01 Assumptions'!$E$48+'02 User Forecast'!H12*10 -> 47557.951 | I9: ='02 User Forecast'!I19*'01 Assumptions'!$E$48+'02 User Forecast'!I12*10 -> 53723.983 | ... AK9: ='02 User Forecast'!AK19*'01 Assumptions'!$E$48+'02 User Forecast'!AK12*10 -> 610084.3
A10: AI Processing Cost | B10: ='02 User Forecast'!B12*'01 Assumptions'!$E$46+'02 User Forecast'!B17*'01 Assumptions'!$E$47 -> 145652.5 | C10: ='02 User Forecast'!C12*'01 Assumptions'!$E$46+'02 User Forecast'!C17*'01 Assumptions'!$E$47 -> 190307.16 | D10: ='02 User Forecast'!D12*'01 Assumptions'!$E$46+'02 User Forecast'!D17*'01 Assumptions'!$E$47 -> 236851.57 | E10: ='02 User Forecast'!E12*'01 Assumptions'!$E$46+'02 User Forecast'!E17*'01 Assumptions'!$E$47 -> 285463.7 | F10: ='02 User Forecast'!F12*'01 Assumptions'!$E$46+'02 User Forecast'!F17*'01 Assumptions'!$E$47 -> 336332.93 | G10: ='02 User Forecast'!G12*'01 Assumptions'!$E$46+'02 User Forecast'!G17*'01 Assumptions'!$E$47 -> 389660.96 | H10: ='02 User Forecast'!H12*'01 Assumptions'!$E$46+'02 User Forecast'!H17*'01 Assumptions'!$E$47 -> 445662.76 | I10: ='02 User Forecast'!I12*'01 Assumptions'!$E$46+'02 User Forecast'!I17*'01 Assumptions'!$E$47 -> 504567.67 | ... AK10: ='02 User Forecast'!AK12*'01 Assumptions'!$E$46+'02 User Forecast'!AK17*'01 Assumptions'!$E$47 -> 5048637
A11: Payment Gateway Fees | B11: =('03 Revenue Forecast'!B8+'03 Revenue Forecast'!B10+'03 Revenue Forecast'!B12)*'01 Assumptions'!$E$45 -> 176250 | C11: =('03 Revenue Forecast'!C8+'03 Revenue Forecast'!C10+'03 Revenue Forecast'!C12)*'01 Assumptions'!$E$45 -> 192075 | D11: =('03 Revenue Forecast'!D8+'03 Revenue Forecast'!D10+'03 Revenue Forecast'!D12)*'01 Assumptions'!$E$45 -> 209322.75 | E11: =('03 Revenue Forecast'!E8+'03 Revenue Forecast'!E10+'03 Revenue Forecast'!E12)*'01 Assumptions'!$E$45 -> 228121.33 | F11: =('03 Revenue Forecast'!F8+'03 Revenue Forecast'!F10+'03 Revenue Forecast'!F12)*'01 Assumptions'!$E$45 -> 248610.35 | G11: =('03 Revenue Forecast'!G8+'03 Revenue Forecast'!G10+'03 Revenue Forecast'!G12)*'01 Assumptions'!$E$45 -> 270942.04 | H11: =('03 Revenue Forecast'!H8+'03 Revenue Forecast'!H10+'03 Revenue Forecast'!H12)*'01 Assumptions'!$E$45 -> 295282.31 | I11: =('03 Revenue Forecast'!I8+'03 Revenue Forecast'!I10+'03 Revenue Forecast'!I12)*'01 Assumptions'!$E$45 -> 321812.06 | ... AK11: =('03 Revenue Forecast'!AK8+'03 Revenue Forecast'!AK10+'03 Revenue Forecast'!AK12)*'01 Assumptions'!$E$45 -> 3592303.3
A12: Total Direct Service Costs | B12: =SUM(B6:B11) -> 4068672.5 | C12: =SUM(C6:C11) -> 4205116.5 | D12: =SUM(D6:D11) -> 4348388.8 | E12: =SUM(E6:E11) -> 4499082.4 | F12: =SUM(F6:F11) -> 4657833.6 | G12: =SUM(G6:G11) -> 4825326.8 | H12: =SUM(H6:H11) -> 5002297.9 | I12: =SUM(I6:I11) -> 5189538.3 | ... AK12: =SUM(AK6:AK11) -> 21008278
A13: Customer Support Cost | B13: ='01 Assumptions'!$E$37+'02 User Forecast'!B12*60+'02 User Forecast'!B20*3000 -> 950265 | C13: ='01 Assumptions'!$E$37+'02 User Forecast'!C12*60+'02 User Forecast'!C20*3000 -> 973435.72 | D13: ='01 Assumptions'!$E$37+'02 User Forecast'!D12*60+'02 User Forecast'!D20*3000 -> 997327.95 | E13: ='01 Assumptions'!$E$37+'02 User Forecast'!E12*60+'02 User Forecast'!E20*3000 -> 1022010.9 | F13: ='01 Assumptions'!$E$37+'02 User Forecast'!F12*60+'02 User Forecast'!F20*3000 -> 1047557.6 | G13: ='01 Assumptions'!$E$37+'02 User Forecast'!G12*60+'02 User Forecast'!G20*3000 -> 1074044.9 | H13: ='01 Assumptions'!$E$37+'02 User Forecast'!H12*60+'02 User Forecast'!H20*3000 -> 1101554 | I13: ='01 Assumptions'!$E$37+'02 User Forecast'!I12*60+'02 User Forecast'!I20*3000 -> 1130170.9 | ... AK13: ='01 Assumptions'!$E$37+'02 User Forecast'!AK12*60+'02 User Forecast'!AK20*3000 -> 2962109.6
A14: Sales & Marketing Cost | B14: ='01 Assumptions'!$E$33+'02 User Forecast'!B14*500 -> 1675000 | C14: ='01 Assumptions'!$E$33+'02 User Forecast'!C14*500 -> 1686375 | D14: ='01 Assumptions'!$E$33+'02 User Forecast'!D14*500 -> 1698489.4 | E14: ='01 Assumptions'!$E$33+'02 User Forecast'!E14*500 -> 1711391.2 | F14: ='01 Assumptions'!$E$33+'02 User Forecast'!F14*500 -> 1725131.6 | G14: ='01 Assumptions'!$E$33+'02 User Forecast'!G14*500 -> 1739765.2 | H14: ='01 Assumptions'!$E$33+'02 User Forecast'!H14*500 -> 1755349.9 | I14: ='01 Assumptions'!$E$33+'02 User Forecast'!I14*500 -> 1771947.6 | ... AK14: ='01 Assumptions'!$E$33+'02 User Forecast'!AK14*500 -> 3085894.6
A15: Partner Commission | B15: ='03 Revenue Forecast'!B16*'01 Assumptions'!$E$32 -> 70014.562 | C15: ='03 Revenue Forecast'!C16*'01 Assumptions'!$E$32 -> 92323.615 | D15: ='03 Revenue Forecast'!D16*'01 Assumptions'!$E$32 -> 115368.78 | E15: ='03 Revenue Forecast'!E16*'01 Assumptions'!$E$32 -> 139219.87 | F15: ='03 Revenue Forecast'!F16*'01 Assumptions'!$E$32 -> 163951.06 | G15: ='03 Revenue Forecast'!G16*'01 Assumptions'!$E$32 -> 189641.32 | H15: ='03 Revenue Forecast'!H16*'01 Assumptions'!$E$32 -> 216374.68 | I15: ='03 Revenue Forecast'!I16*'01 Assumptions'!$E$32 -> 244240.73 | ... AK15: ='03 Revenue Forecast'!AK16*'01 Assumptions'!$E$32 -> 2149633.9
A16: DevOps/Security Cost | B16: ='01 Assumptions'!$E$36 -> 1200000 | C16: ='01 Assumptions'!$E$36 -> 1200000 | D16: ='01 Assumptions'!$E$36 -> 1200000 | E16: ='01 Assumptions'!$E$36 -> 1200000 | F16: ='01 Assumptions'!$E$36 -> 1200000 | G16: ='01 Assumptions'!$E$36 -> 1200000 | H16: ='01 Assumptions'!$E$36 -> 1200000 | I16: ='01 Assumptions'!$E$36 -> 1200000 | ... AK16: ='01 Assumptions'!$E$36 -> 1200000
A17: General Admin Cost | B17: ='01 Assumptions'!$E$38 -> 1400000 | C17: ='01 Assumptions'!$E$38 -> 1400000 | D17: ='01 Assumptions'!$E$38 -> 1400000 | E17: ='01 Assumptions'!$E$38 -> 1400000 | F17: ='01 Assumptions'!$E$38 -> 1400000 | G17: ='01 Assumptions'!$E$38 -> 1400000 | H17: ='01 Assumptions'!$E$38 -> 1400000 | I17: ='01 Assumptions'!$E$38 -> 1400000 | ... AK17: ='01 Assumptions'!$E$38 -> 1400000
A18: Total Operating Costs | B18: =SUM(B13:B17) -> 5295279.6 | C18: =SUM(C13:C17) -> 5352134.3 | D18: =SUM(D13:D17) -> 5411186.1 | E18: =SUM(E13:E17) -> 5472622 | F18: =SUM(F13:F17) -> 5536640.2 | G18: =SUM(G13:G17) -> 5603451.4 | H18: =SUM(H13:H17) -> 5673278.6 | I18: =SUM(I13:I17) -> 5746359.2 | ... AK18: =SUM(AK13:AK17) -> 10797638
A19: Total Cost | B19: =B12+B18 -> 9363952.1 | C19: =C12+C18 -> 9557250.8 | D19: =D12+D18 -> 9759575 | E19: =E12+E18 -> 9971704.3 | F19: =F12+F18 -> 10194474 | G19: =G12+G18 -> 10428778 | H19: =H12+H18 -> 10675576 | I19: =I12+I18 -> 10935898 | ... AK19: =AK12+AK18 -> 31805916

Sheet 05 Profitability
A1: 05 Profitability
A2: Gross margin, EBITDA, cash flow and cumulative profitability
A5: Metric | B5: Month 1 | C5: Month 2 | D5: Month 3 | E5: Month 4 | F5: Month 5 | G5: Month 6 | H5: Month 7 | I5: Month 8 | J5: Month 9 | K5: Month 10 | L5: Month 11 | M5: Month 12 | N5: Month 13 | O5: Month 14 | P5: Month 15 | Q5: Month 16 | R5: Month 17 | S5: Month 18 | T5: Month 19 | U5: Month 20 | V5: Month 21 | W5: Month 22 | X5: Month 23 | Y5: Month 24 | Z5: Month 25 | AA5: Month 26 | AB5: Month 27 | AC5: Month 28 | AD5: Month 29 | AE5: Month 30 | AF5: Month 31 | AG5: Month 32 | AH5: Month 33 | AI5: Month 34 | AJ5: Month 35 | AK5: Month 36
A6: Total Konn3ct Revenue | B6: ='03 Revenue Forecast'!B17 -> 5134401.2 | C6: ='03 Revenue Forecast'!C17 -> 6770398.5 | D6: ='03 Revenue Forecast'!D17 -> 8460377.3 | E6: ='03 Revenue Forecast'!E17 -> 10209457 | F6: ='03 Revenue Forecast'!F17 -> 12023078 | G6: ='03 Revenue Forecast'!G17 -> 13907030 | H6: ='03 Revenue Forecast'!H17 -> 15867476 | I6: ='03 Revenue Forecast'!I17 -> 17910987 | ... AK6: ='03 Revenue Forecast'!AK17 -> 1.5763982e+08
A7: Direct Service Costs | B7: ='04 Cost Forecast'!B12 -> 4068672.5 | C7: ='04 Cost Forecast'!C12 -> 4205116.5 | D7: ='04 Cost Forecast'!D12 -> 4348388.8 | E7: ='04 Cost Forecast'!E12 -> 4499082.4 | F7: ='04 Cost Forecast'!F12 -> 4657833.6 | G7: ='04 Cost Forecast'!G12 -> 4825326.8 | H7: ='04 Cost Forecast'!H12 -> 5002297.9 | I7: ='04 Cost Forecast'!I12 -> 5189538.3 | ... AK7: ='04 Cost Forecast'!AK12 -> 21008278
A8: Gross Profit | B8: =B6-B7 -> 1065728.8 | C8: =C6-C7 -> 2565282 | D8: =D6-D7 -> 4111988.5 | E8: =E6-E7 -> 5710374.4 | F8: =F6-F7 -> 7365244.4 | G8: =G6-G7 -> 9081703 | H8: =H6-H7 -> 10865179 | I8: =I6-I7 -> 12721448 | ... AK8: =AK6-AK7 -> 1.3663154e+08
A9: Gross Margin % | B9: =IFERROR(B8/B6,0) -> 0.20756632 | C9: =IFERROR(C8/C6,0) -> 0.37889675 | D9: =IFERROR(D8/D6,0) -> 0.48602897 | E9: =IFERROR(E8/E6,0) -> 0.55932206 | F9: =IFERROR(F8/F6,0) -> 0.61259225 | G9: =IFERROR(G8/G6,0) -> 0.65302966 | H9: =IFERROR(H8/H6,0) -> 0.68474522 | I9: =IFERROR(I8/I6,0) -> 0.7102595 | ... AK9: =IFERROR(AK8/AK6,0) -> 0.86673241
A10: Operating Costs | B10: ='04 Cost Forecast'!B18 -> 5295279.6 | C10: ='04 Cost Forecast'!C18 -> 5352134.3 | D10: ='04 Cost Forecast'!D18 -> 5411186.1 | E10: ='04 Cost Forecast'!E18 -> 5472622 | F10: ='04 Cost Forecast'!F18 -> 5536640.2 | G10: ='04 Cost Forecast'!G18 -> 5603451.4 | H10: ='04 Cost Forecast'!H18 -> 5673278.6 | I10: ='04 Cost Forecast'!I18 -> 5746359.2 | ... AK10: ='04 Cost Forecast'!AK18 -> 10797638
A11: EBITDA | B11: =B8-B10 -> -4229550.8 | C11: =C8-C10 -> -2786852.3 | D11: =D8-D10 -> -1299197.6 | E11: =E8-E10 -> 237752.45 | F11: =F8-F10 -> 1828604.1 | G11: =G8-G10 -> 3478251.6 | H11: =H8-H10 -> 5191900 | I11: =I8-I10 -> 6975089.1 | ... AK11: =AK8-AK10 -> 1.258339e+08
A12: EBITDA Margin % | B12: =IFERROR(B11/B6,0) -> -0.8237671 | C12: =IFERROR(C11/C6,0) -> -0.41162309 | D12: =IFERROR(D11/D6,0) -> -0.15356261 | E12: =IFERROR(E11/E6,0) -> 0.023287473 | F12: =IFERROR(F11/F6,0) -> 0.15209118 | G12: =IFERROR(G11/G6,0) -> 0.25010744 | H12: =IFERROR(H11/H6,0) -> 0.32720389 | I12: =IFERROR(I11/I6,0) -> 0.38943076 | ... AK12: =IFERROR(AK11/AK6,0) -> 0.79823679
A13: Taxes / Other Placeholder | B13: =IF(B11>0,B11*0,0) -> 0 | C13: =IF(C11>0,C11*0,0) -> 0 | D13: =IF(D11>0,D11*0,0) -> 0 | E13: =IF(E11>0,E11*0,0) -> 0 | F13: =IF(F11>0,F11*0,0) -> 0 | G13: =IF(G11>0,G11*0,0) -> 0 | H13: =IF(H11>0,H11*0,0) -> 0 | I13: =IF(I11>0,I11*0,0) -> 0 | ... AK13: =IF(AK11>0,AK11*0,0) -> 0
A14: Net Profit | B14: =B11-B13 -> -4229550.8 | C14: =C11-C13 -> -2786852.3 | D14: =D11-D13 -> -1299197.6 | E14: =E11-E13 -> 237752.45 | F14: =F11-F13 -> 1828604.1 | G14: =G11-G13 -> 3478251.6 | H14: =H11-H13 -> 5191900 | I14: =I11-I13 -> 6975089.1 | ... AK14: =AK11-AK13 -> 1.258339e+08
A15: Opening Cash | B15: ='01 Assumptions'!$E$49 -> 10000000 | C15: =B17 -> 5770449.2 | D15: =C17 -> 2983596.8 | E15: =D17 -> 1684399.2 | F15: =E17 -> 1922151.7 | G15: =F17 -> 3750755.8 | H15: =G17 -> 7229007.4 | I15: =H17 -> 12420907 | J15: =I17 -> 19395997 | ... AK15: =AJ17 -> 1.3766972e+09
A16: Net Cash Flow | B16: =B14 -> -4229550.8 | C16: =C14 -> -2786852.3 | D16: =D14 -> -1299197.6 | E16: =E14 -> 237752.45 | F16: =F14 -> 1828604.1 | G16: =G14 -> 3478251.6 | H16: =H14 -> 5191900 | I16: =I14 -> 6975089.1 | ... AK16: =AK14 -> 1.258339e+08
A17: Closing Cash | B17: =B15+B16 -> 5770449.2 | C17: =C15+C16 -> 2983596.8 | D17: =D15+D16 -> 1684399.2 | E17: =E15+E16 -> 1922151.7 | F17: =F15+F16 -> 3750755.8 | G17: =G15+G16 -> 7229007.4 | H17: =H15+H16 -> 12420907 | I17: =I15+I16 -> 19395997 | ... AK17: =AK15+AK16 -> 1.5025311e+09
A18: Cumulative EBITDA | B18: =SUM($B$11:B11) -> -4229550.8 | C18: =SUM($B$11:C11) -> -7016403.2 | D18: =SUM($B$11:D11) -> -8315600.8 | E18: =SUM($B$11:E11) -> -8077848.3 | F18: =SUM($B$11:F11) -> -6249244.2 | G18: =SUM($B$11:G11) -> -2770992.6 | H18: =SUM($B$11:H11) -> 2420907.4 | I18: =SUM($B$11:I11) -> 9395996.5 | ... AK18: =SUM($B$11:AK11) -> 1.4925311e+09

Sheet 06 Gross Margin
A1: 06 Gross Margin by Revenue Stream
A2: Summary of stream profitability across the full 36-month forecast
A4: Revenue Stream | B4: Total Revenue | C4: Direct Cost % | D4: Direct Cost | E4: Gross Profit | F4: Gross Margin % | G4: Strategic Note
A5: Meeting Subscriptions | B5: =SUM('03 Revenue Forecast'!B6:AK6) -> 1.2133918e+09 | C5: ='01 Assumptions'!$E$39 -> 0.15 | D5: =B5*C5 -> 1.8200877e+08 | E5: =B5-D5 -> 1.031383e+09 | F5: =IFERROR(E5/B5,0) -> 0.85 | G5: Core recurring revenue engine
A6: Meeting Add-ons | B6: =SUM('03 Revenue Forecast'!B7:AK7) -> 1.0833856e+08 | C6: ='01 Assumptions'!$E$39 -> 0.15 | D6: =B6*C6 -> 16250783 | E6: =B6-D6 -> 92087772 | F6: =IFERROR(E6/B6,0) -> 0.85 | G6: Capacity, AI, storage and support upgrades
A7: Webinar / Event Fees | B7: =SUM('03 Revenue Forecast'!B9:AK9) -> 2.9751715e+08 | C7: ='01 Assumptions'!$E$40 -> 0.32 | D7: =B7*C7 -> 95205488 | E7: =B7-D7 -> 2.0231166e+08 | F7: =IFERROR(E7/B7,0) -> 0.68 | G7: Event-driven monetization and lead generation
A8: Paid Replays | B8: =SUM('03 Revenue Forecast'!B11:AK11) -> 59825361 | C8: ='01 Assumptions'!$E$41 -> 0.18 | D8: =B8*C8 -> 10768565 | E8: =B8-D8 -> 49056796 | F8: =IFERROR(E8/B8,0) -> 0.82 | G8: High-potential content commerce
A9: Donations / Contributions | B9: =SUM('03 Revenue Forecast'!B13:AK13) -> 5613064.4 | C9: ='01 Assumptions'!$E$42 -> 0.06 | D9: =B9*C9 -> 336783.87 | E9: =B9-D9 -> 5276280.6 | F9: =IFERROR(E9/B9,0) -> 0.94 | G9: Community and faith-based contribution flow
A10: Enterprise | B10: =SUM('03 Revenue Forecast'!B14:AK14) -> 174150000 | C10: ='01 Assumptions'!$E$43 -> 0.22 | D10: =B10*C10 -> 38313000 | E10: =B10-D10 -> 135837000 | F10: =IFERROR(E10/B10,0) -> 0.78 | G10: Institutional recurring accounts
A11: API / Embedded | B11: =SUM('03 Revenue Forecast'!B15:AK15) -> 46170000 | C11: ='01 Assumptions'!$E$44 -> 0.38 | D11: =B11*C11 -> 17544600 | E11: =B11-D11 -> 28625400 | F11: =IFERROR(E11/B11,0) -> 0.62 | G11: Developer and platform infrastructure revenue
A12: Partner-Driven Revenue | B12: =SUM('03 Revenue Forecast'!B16:AK16) -> 1.9050059e+08 | C12: ='01 Assumptions'!$E$32 -> 0.15 | D12: =B12*C12 -> 28575089 | E12: =B12-D12 -> 1.6192551e+08 | F12: =IFERROR(E12/B12,0) -> 0.85 | G12: Commissionable channel-driven revenue
A13: Total | B13: =SUM(B5:B12) -> 2.0955065e+09 | D13: =SUM(D5:D12) -> 3.8900308e+08 | E13: =SUM(E5:E12) -> 1.7065035e+09 | F13: =IFERROR(E13/B13,0) -> 0.81436322 | G13: Blended gross margin

Sheet 07 CAC LTV
A1: 07 CAC, LTV and Retention Economics
A2: Unit economics: acquisition cost, ARPU, LTV, churn, payback and retention
A5: Metric | B5: Month 1 | C5: Month 2 | D5: Month 3 | E5: Month 4 | F5: Month 5 | G5: Month 6 | H5: Month 7 | I5: Month 8 | J5: Month 9 | K5: Month 10 | L5: Month 11 | M5: Month 12 | N5: Month 13 | O5: Month 14 | P5: Month 15 | Q5: Month 16 | R5: Month 17 | S5: Month 18 | T5: Month 19 | U5: Month 20 | V5: Month 21 | W5: Month 22 | X5: Month 23 | Y5: Month 24 | Z5: Month 25 | AA5: Month 26 | AB5: Month 27 | AC5: Month 28 | AD5: Month 29 | AE5: Month 30 | AF5: Month 31 | AG5: Month 32 | AH5: Month 33 | AI5: Month 34 | AJ5: Month 35 | AK5: Month 36
A6: New Paid Users | B6: ='02 User Forecast'!B14 -> 350 | C6: ='02 User Forecast'!C14 -> 372.75 | D6: ='02 User Forecast'!D14 -> 396.97875 | E6: ='02 User Forecast'!E14 -> 422.78237 | F6: ='02 User Forecast'!F14 -> 450.26322 | G6: ='02 User Forecast'!G14 -> 479.53033 | H6: ='02 User Forecast'!H14 -> 510.6998 | I6: ='02 User Forecast'!I14 -> 543.89529 | ... AK6: ='02 User Forecast'!AK14 -> 3171.7892
A7: Sales & Marketing Spend | B7: ='04 Cost Forecast'!B14 -> 1675000 | C7: ='04 Cost Forecast'!C14 -> 1686375 | D7: ='04 Cost Forecast'!D14 -> 1698489.4 | E7: ='04 Cost Forecast'!E14 -> 1711391.2 | F7: ='04 Cost Forecast'!F14 -> 1725131.6 | G7: ='04 Cost Forecast'!G14 -> 1739765.2 | H7: ='04 Cost Forecast'!H14 -> 1755349.9 | I7: ='04 Cost Forecast'!I14 -> 1771947.6 | ... AK7: ='04 Cost Forecast'!AK14 -> 3085894.6
A8: Blended CAC | B8: =IFERROR(B7/B6,0) -> 4785.7143 | C8: =IFERROR(C7/C6,0) -> 4524.1449 | D8: =IFERROR(D7/D6,0) -> 4278.5398 | E8: =IFERROR(E7/E6,0) -> 4047.9247 | F8: =IFERROR(F7/F6,0) -> 3831.3847 | G8: =IFERROR(G7/G6,0) -> 3628.0607 | H8: =IFERROR(H7/H6,0) -> 3437.1462 | I8: =IFERROR(I7/I6,0) -> 3257.8838 | ... AK8: =IFERROR(AK7/AK6,0) -> 972.9192
A9: Paid Users | B9: ='02 User Forecast'!B12 -> 687.75 | C9: ='02 User Forecast'!C12 -> 1036.4288 | D9: ='02 User Forecast'!D12 -> 1397.1325 | E9: ='02 User Forecast'!E12 -> 1771.0152 | F9: ='02 User Forecast'!F12 -> 2159.2929 | G9: ='02 User Forecast'!G12 -> 2563.248 | H9: ='02 User Forecast'!H12 -> 2984.2341 | I9: ='02 User Forecast'!I12 -> 3423.6812 | ... AK9: ='02 User Forecast'!AK12 -> 32905.993
A10: ARPU | B10: =IFERROR(('03 Revenue Forecast'!B6+'03 Revenue Forecast'!B7)/B9,0) -> 3050 | C10: =IFERROR(('03 Revenue Forecast'!C6+'03 Revenue Forecast'!C7)/C9,0) -> 3050 | D10: =IFERROR(('03 Revenue Forecast'!D6+'03 Revenue Forecast'!D7)/D9,0) -> 3050 | E10: =IFERROR(('03 Revenue Forecast'!E6+'03 Revenue Forecast'!E7)/E9,0) -> 3050 | F10: =IFERROR(('03 Revenue Forecast'!F6+'03 Revenue Forecast'!F7)/F9,0) -> 3050 | G10: =IFERROR(('03 Revenue Forecast'!G6+'03 Revenue Forecast'!G7)/G9,0) -> 3050 | H10: =IFERROR(('03 Revenue Forecast'!H6+'03 Revenue Forecast'!H7)/H9,0) -> 3050 | I10: =IFERROR(('03 Revenue Forecast'!I6+'03 Revenue Forecast'!I7)/I9,0) -> 3050 | ... AK10: =IFERROR(('03 Revenue Forecast'!AK6+'03 Revenue Forecast'!AK7)/AK9,0) -> 3050
A11: Gross Margin % | B11: ='05 Profitability'!B9 -> 0.20756632 | C11: ='05 Profitability'!C9 -> 0.37889675 | D11: ='05 Profitability'!D9 -> 0.48602897 | E11: ='05 Profitability'!E9 -> 0.55932206 | F11: ='05 Profitability'!F9 -> 0.61259225 | G11: ='05 Profitability'!G9 -> 0.65302966 | H11: ='05 Profitability'!H9 -> 0.68474522 | I11: ='05 Profitability'!I9 -> 0.7102595 | ... AK11: ='05 Profitability'!AK9 -> 0.86673241
A12: Monthly Churn % | B12: ='01 Assumptions'!$E$10 -> 0.035 | C12: ='01 Assumptions'!$E$10 -> 0.035 | D12: ='01 Assumptions'!$E$10 -> 0.035 | E12: ='01 Assumptions'!$E$10 -> 0.035 | F12: ='01 Assumptions'!$E$10 -> 0.035 | G12: ='01 Assumptions'!$E$10 -> 0.035 | H12: ='01 Assumptions'!$E$10 -> 0.035 | I12: ='01 Assumptions'!$E$10 -> 0.035 | ... AK12: ='01 Assumptions'!$E$10 -> 0.035
A13: Estimated LTV | B13: =IFERROR(B10*B11/B12,0) -> 18087.922 | C13: =IFERROR(C10*C11/C12,0) -> 33018.146 | D13: =IFERROR(D10*D11/D12,0) -> 42353.953 | E13: =IFERROR(E10*E11/E12,0) -> 48740.923 | F13: =IFERROR(F10*F11/F12,0) -> 53383.039 | G13: =IFERROR(G10*G11/G12,0) -> 56906.871 | H13: =IFERROR(H10*H11/H12,0) -> 59670.655 | I13: =IFERROR(I10*I11/I12,0) -> 61894.042 | ... AK13: =IFERROR(AK10*AK11/AK12,0) -> 75529.539
A14: LTV / CAC | B14: =IFERROR(B13/B8,0) -> 3.7795657 | C14: =IFERROR(C13/C8,0) -> 7.298207 | D14: =IFERROR(D13/D8,0) -> 9.8991607 | E14: =IFERROR(E13/E8,0) -> 12.040966 | F14: =IFERROR(F13/F8,0) -> 13.933093 | G14: =IFERROR(G13/G8,0) -> 15.685203 | H14: =IFERROR(H13/H8,0) -> 17.360523 | I14: =IFERROR(I13/I8,0) -> 18.998235 | ... AK14: =IFERROR(AK13/AK8,0) -> 77.631872
A15: CAC Payback Months | B15: =IFERROR(B8/(B10*B11),0) -> 7.5594474 | C15: =IFERROR(C8/(C10*C11),0) -> 3.9148559 | D15: =IFERROR(D8/(D10*D11),0) -> 2.8862476 | E15: =IFERROR(E8/(E10*E11),0) -> 2.3728519 | F15: =IFERROR(F8/(F10*F11),0) -> 2.0506164 | G15: =IFERROR(G8/(G10*G11),0) -> 1.821553 | H15: =IFERROR(H8/(H10*H11),0) -> 1.6457701 | I15: =IFERROR(I8/(I10*I11),0) -> 1.5038991 | ... AK15: =IFERROR(AK8/(AK10*AK11),0) -> 0.36803735

Sheet 08 Break Even
A1: 08 Break-Even Analysis
A2: Month-by-month view of revenue, total cost, EBITDA, cumulative cash and break-even flag
A4: Month | B4: Revenue | C4: Total Cost | D4: EBITDA | E4: Cumulative EBITDA | F4: Closing Cash | G4: Break-Even Flag
A5: Month 1 | B5: ='05 Profitability'!B6 -> 5134401.2 | C5: ='04 Cost Forecast'!B19 -> 9363952.1 | D5: ='05 Profitability'!B11 -> -4229550.8 | E5: ='05 Profitability'!B18 -> -4229550.8 | F5: ='05 Profitability'!B17 -> 5770449.2 | G5: =IF(E5>0,"Break-even achieved","Not yet") -> Not yet
A6: Month 2 | B6: ='05 Profitability'!C6 -> 6770398.5 | C6: ='04 Cost Forecast'!C19 -> 9557250.8 | D6: ='05 Profitability'!C11 -> -2786852.3 | E6: ='05 Profitability'!C18 -> -7016403.2 | F6: ='05 Profitability'!C17 -> 2983596.8 | G6: =IF(E6>0,"Break-even achieved","Not yet") -> Not yet
A7: Month 3 | B7: ='05 Profitability'!D6 -> 8460377.3 | C7: ='04 Cost Forecast'!D19 -> 9759575 | D7: ='05 Profitability'!D11 -> -1299197.6 | E7: ='05 Profitability'!D18 -> -8315600.8 | F7: ='05 Profitability'!D17 -> 1684399.2 | G7: =IF(E7>0,"Break-even achieved","Not yet") -> Not yet
A8: Month 4 | B8: ='05 Profitability'!E6 -> 10209457 | C8: ='04 Cost Forecast'!E19 -> 9971704.3 | D8: ='05 Profitability'!E11 -> 237752.45 | E8: ='05 Profitability'!E18 -> -8077848.3 | F8: ='05 Profitability'!E17 -> 1922151.7 | G8: =IF(E8>0,"Break-even achieved","Not yet") -> Not yet
A9: Month 5 | B9: ='05 Profitability'!F6 -> 12023078 | C9: ='04 Cost Forecast'!F19 -> 10194474 | D9: ='05 Profitability'!F11 -> 1828604.1 | E9: ='05 Profitability'!F18 -> -6249244.2 | F9: ='05 Profitability'!F17 -> 3750755.8 | G9: =IF(E9>0,"Break-even achieved","Not yet") -> Not yet
A10: Month 6 | B10: ='05 Profitability'!G6 -> 13907030 | C10: ='04 Cost Forecast'!G19 -> 10428778 | D10: ='05 Profitability'!G11 -> 3478251.6 | E10: ='05 Profitability'!G18 -> -2770992.6 | F10: ='05 Profitability'!G17 -> 7229007.4 | G10: =IF(E10>0,"Break-even achieved","Not yet") -> Not yet
A11: Month 7 | B11: ='05 Profitability'!H6 -> 15867476 | C11: ='04 Cost Forecast'!H19 -> 10675576 | D11: ='05 Profitability'!H11 -> 5191900 | E11: ='05 Profitability'!H18 -> 2420907.4 | F11: ='05 Profitability'!H17 -> 12420907 | G11: =IF(E11>0,"Break-even achieved","Not yet") -> Break-even achieved
A12: Month 8 | B12: ='05 Profitability'!I6 -> 17910987 | C12: ='04 Cost Forecast'!I19 -> 10935898 | D12: ='05 Profitability'!I11 -> 6975089.1 | E12: ='05 Profitability'!I18 -> 9395996.5 | F12: ='05 Profitability'!I17 -> 19395997 | G12: =IF(E12>0,"Break-even achieved","Not yet") -> Break-even achieved
A13: Month 9 | B13: ='05 Profitability'!J6 -> 20044565 | C13: ='04 Cost Forecast'!J19 -> 11210846 | D13: ='05 Profitability'!J11 -> 8833719.8 | E13: ='05 Profitability'!J18 -> 18229716 | F13: ='05 Profitability'!J17 -> 28229716 | G13: =IF(E13>0,"Break-even achieved","Not yet") -> Break-even achieved
A14: Month 10 | B14: ='05 Profitability'!K6 -> 22275688 | C14: ='04 Cost Forecast'!K19 -> 11501606 | D14: ='05 Profitability'!K11 -> 10774082 | E14: ='05 Profitability'!K18 -> 29003798 | F14: ='05 Profitability'!K17 -> 39003798 | G14: =IF(E14>0,"Break-even achieved","Not yet") -> Break-even achieved
A15: Month 11 | B15: ='05 Profitability'!L6 -> 24612338 | C15: ='04 Cost Forecast'!L19 -> 11809454 | D15: ='05 Profitability'!L11 -> 12802884 | E15: ='05 Profitability'!L18 -> 41806682 | F15: ='05 Profitability'!L17 -> 51806682 | G15: =IF(E15>0,"Break-even achieved","Not yet") -> Break-even achieved
A16: Month 12 | B16: ='05 Profitability'!M6 -> 27063042 | C16: ='04 Cost Forecast'!M19 -> 12135757 | D16: ='05 Profitability'!M11 -> 14927286 | E16: ='05 Profitability'!M18 -> 56733968 | F16: ='05 Profitability'!M17 -> 66733968 | G16: =IF(E16>0,"Break-even achieved","Not yet") -> Break-even achieved
A17: Month 13 | B17: ='05 Profitability'!N6 -> 29636920 | C17: ='04 Cost Forecast'!N19 -> 12481987 | D17: ='05 Profitability'!N11 -> 17154933 | E17: ='05 Profitability'!N18 -> 73888901 | F17: ='05 Profitability'!N17 -> 83888901 | G17: =IF(E17>0,"Break-even achieved","Not yet") -> Break-even achieved
A18: Month 14 | B18: ='05 Profitability'!O6 -> 32343723 | C18: ='04 Cost Forecast'!O19 -> 12849728 | D18: ='05 Profitability'!O11 -> 19493995 | E18: ='05 Profitability'!O18 -> 93382896 | F18: ='05 Profitability'!O17 -> 1.033829e+08 | G18: =IF(E18>0,"Break-even achieved","Not yet") -> Break-even achieved
A19: Month 15 | B19: ='05 Profitability'!P6 -> 35193887 | C19: ='04 Cost Forecast'!P19 -> 13240683 | D19: ='05 Profitability'!P11 -> 21953204 | E19: ='05 Profitability'!P18 -> 1.153361e+08 | F19: ='05 Profitability'!P17 -> 1.253361e+08 | G19: =IF(E19>0,"Break-even achieved","Not yet") -> Break-even achieved
A20: Month 16 | B20: ='05 Profitability'!Q6 -> 38198584 | C20: ='04 Cost Forecast'!Q19 -> 13656685 | D20: ='05 Profitability'!Q11 -> 24541899 | E20: ='05 Profitability'!Q18 -> 1.39878e+08 | F20: ='05 Profitability'!Q17 -> 1.49878e+08 | G20: =IF(E20>0,"Break-even achieved","Not yet") -> Break-even achieved
A21: Month 17 | B21: ='05 Profitability'!R6 -> 41369779 | C21: ='04 Cost Forecast'!R19 -> 14099708 | D21: ='05 Profitability'!R11 -> 27270072 | E21: ='05 Profitability'!R18 -> 1.6714807e+08 | F21: ='05 Profitability'!R17 -> 1.7714807e+08 | G21: =IF(E21>0,"Break-even achieved","Not yet") -> Break-even achieved
A22: Month 18 | B22: ='05 Profitability'!S6 -> 44720294 | C22: ='04 Cost Forecast'!S19 -> 14571878 | D22: ='05 Profitability'!S11 -> 30148417 | E22: ='05 Profitability'!S18 -> 1.9729649e+08 | F22: ='05 Profitability'!S17 -> 2.0729649e+08 | G22: =IF(E22>0,"Break-even achieved","Not yet") -> Break-even achieved
A23: Month 19 | B23: ='05 Profitability'!T6 -> 48263871 | C23: ='04 Cost Forecast'!T19 -> 15075485 | D23: ='05 Profitability'!T11 -> 33188386 | E23: ='05 Profitability'!T18 -> 2.3048487e+08 | F23: ='05 Profitability'!T17 -> 2.4048487e+08 | G23: =IF(E23>0,"Break-even achieved","Not yet") -> Break-even achieved
A24: Month 20 | B24: ='05 Profitability'!U6 -> 52015243 | C24: ='04 Cost Forecast'!U19 -> 15612997 | D24: ='05 Profitability'!U11 -> 36402247 | E24: ='05 Profitability'!U18 -> 2.6688712e+08 | F24: ='05 Profitability'!U17 -> 2.7688712e+08 | G24: =IF(E24>0,"Break-even achieved","Not yet") -> Break-even achieved
A25: Month 21 | B25: ='05 Profitability'!V6 -> 55990215 | C25: ='04 Cost Forecast'!V19 -> 16187073 | D25: ='05 Profitability'!V11 -> 39803142 | E25: ='05 Profitability'!V18 -> 3.0669026e+08 | F25: ='05 Profitability'!V17 -> 3.1669026e+08 | G25: =IF(E25>0,"Break-even achieved","Not yet") -> Break-even achieved
A26: Month 22 | B26: ='05 Profitability'!W6 -> 60205744 | C26: ='04 Cost Forecast'!W19 -> 16800581 | D26: ='05 Profitability'!W11 -> 43405163 | E26: ='05 Profitability'!W18 -> 3.5009543e+08 | F26: ='05 Profitability'!W17 -> 3.6009543e+08 | G26: =IF(E26>0,"Break-even achieved","Not yet") -> Break-even achieved
A27: Month 23 | B27: ='05 Profitability'!X6 -> 64680027 | C27: ='04 Cost Forecast'!X19 -> 17456613 | D27: ='05 Profitability'!X11 -> 47223415 | E27: ='05 Profitability'!X18 -> 3.9731884e+08 | F27: ='05 Profitability'!X17 -> 4.0731884e+08 | G27: =IF(E27>0,"Break-even achieved","Not yet") -> Break-even achieved
A28: Month 24 | B28: ='05 Profitability'!Y6 -> 69432604 | C28: ='04 Cost Forecast'!Y19 -> 18158504 | D28: ='05 Profitability'!Y11 -> 51274099 | E28: ='05 Profitability'!Y18 -> 4.4859294e+08 | F28: ='05 Profitability'!Y17 -> 4.5859294e+08 | G28: =IF(E28>0,"Break-even achieved","Not yet") -> Break-even achieved
A29: Month 25 | B29: ='05 Profitability'!Z6 -> 74484453 | C29: ='04 Cost Forecast'!Z19 -> 18909853 | D29: ='05 Profitability'!Z11 -> 55574600 | E29: ='05 Profitability'!Z18 -> 5.0416754e+08 | F29: ='05 Profitability'!Z17 -> 5.1416754e+08 | G29: =IF(E29>0,"Break-even achieved","Not yet") -> Break-even achieved
A30: Month 26 | B30: ='05 Profitability'!AA6 -> 79858112 | C30: ='04 Cost Forecast'!AA19 -> 19714542 | D30: ='05 Profitability'!AA11 -> 60143570 | E30: ='05 Profitability'!AA18 -> 5.6431111e+08 | F30: ='05 Profitability'!AA17 -> 5.7431111e+08 | G30: =IF(E30>0,"Break-even achieved","Not yet") -> Break-even achieved
A31: Month 27 | B31: ='05 Profitability'!AB6 -> 85577793 | C31: ='04 Cost Forecast'!AB19 -> 20576762 | D31: ='05 Profitability'!AB11 -> 65001031 | E31: ='05 Profitability'!AB18 -> 6.2931214e+08 | F31: ='05 Profitability'!AB17 -> 6.3931214e+08 | G31: =IF(E31>0,"Break-even achieved","Not yet") -> Break-even achieved
A32: Month 28 | B32: ='05 Profitability'!AC6 -> 91669519 | C32: ='04 Cost Forecast'!AC19 -> 21501036 | D32: ='05 Profitability'!AC11 -> 70168483 | E32: ='05 Profitability'!AC18 -> 6.9948062e+08 | F32: ='05 Profitability'!AC17 -> 7.0948062e+08 | G32: =IF(E32>0,"Break-even achieved","Not yet") -> Break-even achieved
A33: Month 29 | B33: ='05 Profitability'!AD6 -> 98161261 | C33: ='04 Cost Forecast'!AD19 -> 22492248 | D33: ='05 Profitability'!AD11 -> 75669013 | E33: ='05 Profitability'!AD18 -> 7.7514964e+08 | F33: ='05 Profitability'!AD17 -> 7.8514964e+08 | G33: =IF(E33>0,"Break-even achieved","Not yet") -> Break-even achieved
A34: Month 30 | B34: ='05 Profitability'!AE6 -> 1.0508309e+08 | C34: ='04 Cost Forecast'!AE19 -> 23555672 | D34: ='05 Profitability'!AE11 -> 81527421 | E34: ='05 Profitability'!AE18 -> 8.5667706e+08 | F34: ='05 Profitability'!AE17 -> 8.6667706e+08 | G34: =IF(E34>0,"Break-even achieved","Not yet") -> Break-even achieved
A35: Month 31 | B35: ='05 Profitability'!AF6 -> 1.1246736e+08 | C35: ='04 Cost Forecast'!AF19 -> 24697005 | D35: ='05 Profitability'!AF11 -> 87770355 | E35: ='05 Profitability'!AF18 -> 9.4444741e+08 | F35: ='05 Profitability'!AF17 -> 9.5444741e+08 | G35: =IF(E35>0,"Break-even achieved","Not yet") -> Break-even achieved
A36: Month 32 | B36: ='05 Profitability'!AG6 -> 1.2034885e+08 | C36: ='04 Cost Forecast'!AG19 -> 25922401 | D36: ='05 Profitability'!AG11 -> 94426450 | E36: ='05 Profitability'!AG18 -> 1.0388739e+09 | F36: ='05 Profitability'!AG17 -> 1.0488739e+09 | G36: =IF(E36>0,"Break-even achieved","Not yet") -> Break-even achieved
A37: Month 33 | B37: ='05 Profitability'!AH6 -> 1.28765e+08 | C37: ='04 Cost Forecast'!AH19 -> 27238510 | D37: ='05 Profitability'!AH11 -> 1.0152649e+08 | E37: ='05 Profitability'!AH18 -> 1.1404004e+09 | F37: ='05 Profitability'!AH17 -> 1.1504004e+09 | G37: =IF(E37>0,"Break-even achieved","Not yet") -> Break-even achieved
A38: Month 34 | B38: ='05 Profitability'!AI6 -> 1.3775609e+08 | C38: ='04 Cost Forecast'!AI19 -> 28652516 | D38: ='05 Profitability'!AI11 -> 1.0910357e+08 | E38: ='05 Profitability'!AI18 -> 1.2495039e+09 | F38: ='05 Profitability'!AI17 -> 1.2595039e+09 | G38: =IF(E38>0,"Break-even achieved","Not yet") -> Break-even achieved
A39: Month 35 | B39: ='05 Profitability'!AJ6 -> 1.4736547e+08 | C39: ='04 Cost Forecast'!AJ19 -> 30172186 | D39: ='05 Profitability'!AJ11 -> 1.1719328e+08 | E39: ='05 Profitability'!AJ18 -> 1.3666972e+09 | F39: ='05 Profitability'!AJ17 -> 1.3766972e+09 | G39: =IF(E39>0,"Break-even achieved","Not yet") -> Break-even achieved
A40: Month 36 | B40: ='05 Profitability'!AK6 -> 1.5763982e+08 | C40: ='04 Cost Forecast'!AK19 -> 31805916 | D40: ='05 Profitability'!AK11 -> 1.258339e+08 | E40: ='05 Profitability'!AK18 -> 1.4925311e+09 | F40: ='05 Profitability'!AK17 -> 1.5025311e+09 | G40: =IF(E40>0,"Break-even achieved","Not yet") -> Break-even achieved

Sheet 09 Scenarios
A1: 09 Conservative, Base and Aggressive Scenario Analysis
A2: High-level comparison of the three commercial growth cases
A4: Scenario | B4: Free User Growth | C4: Conversion | D4: Churn | E4: ARPU | F4: Month 36 Free Users | G4: Month 36 Paid Users | H4: Month 36 Revenue | I4: Estimated EBITDA | J4: LTV/CAC View | K4: Interpretation
A5: Conservative | B5: ='01 Assumptions'!B8 -> 0.06 | C5: ='01 Assumptions'!B9 -> 0.018 | D5: ='01 Assumptions'!B10 -> 0.055 | E5: ='01 Assumptions'!B11 -> 1800 | F5: ='01 Assumptions'!B6*(1+B5)^36 -> 40736.26 | G5: ='01 Assumptions'!B7*(1-D5)^36+(F5*C5) -> 752.82473 | H5: =G5*E5+('01 Assumptions'!B13*(1+'01 Assumptions'!B14)^36*'01 Assumptions'!B15*'01 Assumptions'!B16*'01 Assumptions'!B17) -> 1749062 | I5: =H5*0.25 -> 437265.51 | J5: =IF(C5<0.025,"Weak",IF(C5<0.05,"Developing","Strong")) -> Weak | K5: Useful downside case for cash protection and slower adoption.
A6: Base | B6: ='01 Assumptions'!C8 -> 0.1 | C6: ='01 Assumptions'!C9 -> 0.035 | D6: ='01 Assumptions'!C10 -> 0.035 | E6: ='01 Assumptions'!C11 -> 2800 | F6: ='01 Assumptions'!C6*(1+B6)^36 -> 309126.81 | G6: ='01 Assumptions'!C7*(1-D6)^36+(F6*C6) -> 10916.501 | H6: =G6*E6+('01 Assumptions'!C13*(1+'01 Assumptions'!C14)^36*'01 Assumptions'!C15*'01 Assumptions'!C16*'01 Assumptions'!C17) -> 58602745 | I6: =H6*0.25 -> 14650686 | J6: =IF(C6<0.025,"Weak",IF(C6<0.05,"Developing","Strong")) -> Developing | K6: Planning case for management targets and operating discipline.
A7: Aggressive | B7: ='01 Assumptions'!D8 -> 0.16 | C7: ='01 Assumptions'!D9 -> 0.06 | D7: ='01 Assumptions'!D10 -> 0.022 | E7: ='01 Assumptions'!D11 -> 4200 | F7: ='01 Assumptions'!D6*(1+B7)^36 -> 4183286.5 | G7: ='01 Assumptions'!D7*(1-D7)^36+(F7*C7) -> 251333.9 | H7: =G7*E7+('01 Assumptions'!D13*(1+'01 Assumptions'!D14)^36*'01 Assumptions'!D15*'01 Assumptions'!D16*'01 Assumptions'!D17) -> 2.6062649e+09 | I7: =H7*0.25 -> 6.5156622e+08 | J7: =IF(C7<0.025,"Weak",IF(C7<0.05,"Developing","Strong")) -> Strong | K7: Upside case requiring stronger infrastructure, support and sales execution.

Sheet 10 Meeting Subs
A1: 10 Meeting Subscription Revenue Worksheet
A2: Plan design worksheet for normal meeting subscription revenue
A4: Plan | B4: Monthly Price | C4: Target Customers | D4: Estimated Accounts | E4: Hosts per Account | F4: Monthly Revenue | G4: Direct Cost % | H4: Gross Profit
A5: Free | B5: 0 | C5: Entry adoption and activation | D5: 10000 | E5: 1 | F5: =B5*D5 -> 0 | G5: 0.25 | H5: =F5*(1-G5) -> 0
A6: Starter | B6: 2500 | C6: Individuals and small teams | D6: 800 | E6: 1 | F6: =B6*D6 -> 2000000 | G6: 0.18 | H6: =F6*(1-G6) -> 1640000
A7: Business | B7: 12000 | C7: SMEs, schools and associations | D7: 200 | E7: 4 | F7: =B7*D7 -> 2400000 | G7: 0.15 | H7: =F7*(1-G7) -> 2040000
A8: Enterprise | B8: 250000 | C8: Institutions and large organizations | D8: 10 | E8: 20 | F8: =B8*D8 -> 2500000 | G8: 0.22 | H8: =F8*(1-G8) -> 1950000
A9: Private / API | B9: 600000 | C9: Private deployment and API customers | D9: 3 | E9: 1 | F9: =B9*D9 -> 1800000 | G9: 0.35 | H9: =F9*(1-G9) -> 1170000
A10: Total | F10: =SUM(F5:F9) -> 8700000 | H10: =SUM(H5:H9) -> 6800000

Sheet 11 Webinar Events
A1: 11 Webinar and Event Monetization Worksheet
A2: Event revenue worksheet for paid webinars, trainings, conferences and public sessions
A4: Event Type | B4: Avg Ticket Price | C4: Tickets/Event | D4: Events/Month | E4: GMV | F4: Platform Fee % | G4: Konn3ct Revenue | H4: Gross Profit
A5: Training Webinar | B5: 3500 | C5: 150 | D5: 10 | E5: =B5*C5*D5 -> 5250000 | F5: 0.12 | G5: =E5*F5 -> 630000 | H5: =G5*(1-'01 Assumptions'!$E$40) -> 428400
A6: Professional Conference | B6: 7500 | C6: 300 | D6: 3 | E6: =B6*C6*D6 -> 6750000 | F6: 0.12 | G6: =E6*F6 -> 810000 | H6: =G6*(1-'01 Assumptions'!$E$40) -> 550800
A7: Faith-Based Conference | B7: 2000 | C7: 1000 | D7: 2 | E7: =B7*C7*D7 -> 4000000 | F7: 0.04 | G7: =E7*F7 -> 160000 | H7: =G7*(1-'01 Assumptions'!$E$40) -> 108800
A8: Association Training | B8: 5000 | C8: 200 | D8: 5 | E8: =B8*C8*D8 -> 5000000 | F8: 0.12 | G8: =E8*F8 -> 600000 | H8: =G8*(1-'01 Assumptions'!$E$40) -> 408000
A9: Public Sector Town Hall | B9: 0 | C9: 500 | D9: 2 | E9: =B9*C9*D9 -> 0 | F9: 0 | G9: =E9*F9 -> 0 | H9: =G9*(1-'01 Assumptions'!$E$40) -> 0
A10: Total | E10: =SUM(E5:E9) -> 21000000 | G10: =SUM(G5:G9) -> 2200000 | H10: =SUM(H5:H9) -> 1496000

Sheet 12 Replay Revenue
A1: 12 Paid Replay and Recording Monetization Worksheet
